[2024-06-19T03:49:36.349+0000] {local_task_job_runner.py:120} INFO - ::group::Pre task execution logs
[2024-06-19T03:49:36.628+0000] {taskinstance.py:2076} INFO - Dependencies all met for dep_context=non-requeueable deps ti=<TaskInstance: extract_data_from_postgres.extract_data manual__2024-06-19T03:45:06.393347+00:00 [queued]>
[2024-06-19T03:49:36.643+0000] {taskinstance.py:2076} INFO - Dependencies all met for dep_context=requeueable deps ti=<TaskInstance: extract_data_from_postgres.extract_data manual__2024-06-19T03:45:06.393347+00:00 [queued]>
[2024-06-19T03:49:36.643+0000] {taskinstance.py:2306} INFO - Starting attempt 1 of 2
[2024-06-19T03:49:36.670+0000] {taskinstance.py:2330} INFO - Executing <Task(PythonOperator): extract_data> on 2024-06-19 03:45:06.393347+00:00
[2024-06-19T03:49:36.681+0000] {warnings.py:112} WARNING - /home/***/.local/lib/python3.12/site-packages/***/task/task_runner/standard_task_runner.py:61: DeprecationWarning: This process (pid=8292) is multi-threaded, use of fork() may lead to deadlocks in the child.
  pid = os.fork()

[2024-06-19T03:49:36.683+0000] {standard_task_runner.py:63} INFO - Started process 8294 to run task
[2024-06-19T03:49:36.684+0000] {standard_task_runner.py:90} INFO - Running: ['***', 'tasks', 'run', 'extract_data_from_postgres', 'extract_data', 'manual__2024-06-19T03:45:06.393347+00:00', '--job-id', '11', '--raw', '--subdir', 'DAGS_FOLDER/extract_data_from_postgres.py', '--cfg-path', '/tmp/tmp4i8jb8w9']
[2024-06-19T03:49:36.688+0000] {standard_task_runner.py:91} INFO - Job 11: Subtask extract_data
[2024-06-19T03:49:36.770+0000] {task_command.py:426} INFO - Running <TaskInstance: extract_data_from_postgres.extract_data manual__2024-06-19T03:45:06.393347+00:00 [running]> on host 7709186783c9
[2024-06-19T03:49:36.916+0000] {taskinstance.py:2648} INFO - Exporting env vars: AIRFLOW_CTX_DAG_OWNER='candratama' AIRFLOW_CTX_DAG_ID='extract_data_from_postgres' AIRFLOW_CTX_TASK_ID='extract_data' AIRFLOW_CTX_EXECUTION_DATE='2024-06-19T03:45:06.393347+00:00' AIRFLOW_CTX_TRY_NUMBER='1' AIRFLOW_CTX_DAG_RUN_ID='manual__2024-06-19T03:45:06.393347+00:00'
[2024-06-19T03:49:36.918+0000] {taskinstance.py:430} INFO - ::endgroup::
[2024-06-19T03:49:36.956+0000] {base.py:84} INFO - Using connection ID '***_db_conn' for task execution.
[2024-06-19T03:49:36.963+0000] {taskinstance.py:441} INFO - ::group::Post task execution logs
[2024-06-19T03:49:36.964+0000] {taskinstance.py:2905} ERROR - Task failed with exception
Traceback (most recent call last):
  File "/home/airflow/.local/lib/python3.12/site-packages/airflow/models/taskinstance.py", line 465, in _execute_task
    result = _execute_callable(context=context, **execute_callable_kwargs)
             ^^^^^^^^^^^^^^^^^^^^^^^^^^^^^^^^^^^^^^^^^^^^^^^^^^^^^^^^^^^^^
  File "/home/airflow/.local/lib/python3.12/site-packages/airflow/models/taskinstance.py", line 432, in _execute_callable
    return execute_callable(context=context, **execute_callable_kwargs)
           ^^^^^^^^^^^^^^^^^^^^^^^^^^^^^^^^^^^^^^^^^^^^^^^^^^^^^^^^^^^^
  File "/home/airflow/.local/lib/python3.12/site-packages/airflow/models/baseoperator.py", line 401, in wrapper
    return func(self, *args, **kwargs)
           ^^^^^^^^^^^^^^^^^^^^^^^^^^^
  File "/home/airflow/.local/lib/python3.12/site-packages/airflow/operators/python.py", line 235, in execute
    return_value = self.execute_callable()
                   ^^^^^^^^^^^^^^^^^^^^^^^
  File "/home/airflow/.local/lib/python3.12/site-packages/airflow/operators/python.py", line 252, in execute_callable
    return self.python_callable(*self.op_args, **self.op_kwargs)
           ^^^^^^^^^^^^^^^^^^^^^^^^^^^^^^^^^^^^^^^^^^^^^^^^^^^^^
  File "/opt/airflow/dags/extract_data_from_postgres.py", line 17, in extract_data_from_postgres
    cursor.execute(sql)
psycopg2.errors.UndefinedTable: relation "ab_permission" does not exist
LINE 1: SELECT * FROM ab_permission
                      ^

[2024-06-19T03:49:36.978+0000] {taskinstance.py:1206} INFO - Marking task as UP_FOR_RETRY. dag_id=extract_data_from_postgres, task_id=extract_data, run_id=manual__2024-06-19T03:45:06.393347+00:00, execution_date=20240619T034506, start_date=20240619T034936, end_date=20240619T034936
[2024-06-19T03:49:36.999+0000] {standard_task_runner.py:110} ERROR - Failed to execute job 11 for task extract_data (relation "ab_permission" does not exist
LINE 1: SELECT * FROM ab_permission
                      ^
; 8294)
[2024-06-19T03:49:37.020+0000] {local_task_job_runner.py:240} INFO - Task exited with return code 1
[2024-06-19T03:49:37.049+0000] {taskinstance.py:3503} INFO - 0 downstream tasks scheduled from follow-on schedule check
[2024-06-19T03:49:37.052+0000] {local_task_job_runner.py:222} INFO - ::endgroup::
