[2024-06-19T07:16:33.388+0000] {local_task_job_runner.py:120} INFO - ::group::Pre task execution logs
[2024-06-19T07:16:33.453+0000] {taskinstance.py:2076} INFO - Dependencies all met for dep_context=non-requeueable deps ti=<TaskInstance: summary_transaction.extract_task scheduled__2024-06-18T07:11:00+00:00 [queued]>
[2024-06-19T07:16:33.496+0000] {taskinstance.py:2076} INFO - Dependencies all met for dep_context=requeueable deps ti=<TaskInstance: summary_transaction.extract_task scheduled__2024-06-18T07:11:00+00:00 [queued]>
[2024-06-19T07:16:33.497+0000] {taskinstance.py:2306} INFO - Starting attempt 2 of 3
[2024-06-19T07:16:33.535+0000] {taskinstance.py:2330} INFO - Executing <Task(PythonOperator): extract_task> on 2024-06-18 07:11:00+00:00
[2024-06-19T07:16:33.567+0000] {warnings.py:112} WARNING - /home/***/.local/lib/python3.12/site-packages/***/task/task_runner/standard_task_runner.py:61: DeprecationWarning: This process (pid=10745) is multi-threaded, use of fork() may lead to deadlocks in the child.
  pid = os.fork()

[2024-06-19T07:16:33.570+0000] {standard_task_runner.py:63} INFO - Started process 10747 to run task
[2024-06-19T07:16:33.579+0000] {standard_task_runner.py:90} INFO - Running: ['***', 'tasks', 'run', 'summary_transaction', 'extract_task', 'scheduled__2024-06-18T07:11:00+00:00', '--job-id', '28', '--raw', '--subdir', 'DAGS_FOLDER/summary_transaction.py', '--cfg-path', '/tmp/tmp1zinhxc1']
[2024-06-19T07:16:33.584+0000] {standard_task_runner.py:91} INFO - Job 28: Subtask extract_task
[2024-06-19T07:16:33.707+0000] {task_command.py:426} INFO - Running <TaskInstance: summary_transaction.extract_task scheduled__2024-06-18T07:11:00+00:00 [running]> on host 7709186783c9
[2024-06-19T07:16:38.049+0000] {taskinstance.py:2648} INFO - Exporting env vars: AIRFLOW_CTX_DAG_OWNER='candratama' AIRFLOW_CTX_DAG_ID='summary_transaction' AIRFLOW_CTX_TASK_ID='extract_task' AIRFLOW_CTX_EXECUTION_DATE='2024-06-18T07:11:00+00:00' AIRFLOW_CTX_TRY_NUMBER='2' AIRFLOW_CTX_DAG_RUN_ID='scheduled__2024-06-18T07:11:00+00:00'
[2024-06-19T07:16:38.051+0000] {taskinstance.py:430} INFO - ::endgroup::
[2024-06-19T07:16:38.098+0000] {base.py:84} INFO - Using connection ID 'dbmaster' for task execution.
[2024-06-19T07:16:48.832+0000] {local_task_job_runner.py:310} WARNING - State of this instance has been externally set to restarting. Terminating instance.
[2024-06-19T07:16:48.834+0000] {local_task_job_runner.py:222} INFO - ::endgroup::
[2024-06-19T07:16:48.836+0000] {process_utils.py:132} INFO - Sending 15 to group 10747. PIDs of all processes in the group: [10747]
[2024-06-19T07:16:48.837+0000] {process_utils.py:87} INFO - Sending the signal 15 to group 10747
[2024-06-19T07:16:54.236+0000] {taskinstance.py:2611} ERROR - Received SIGTERM. Terminating subprocesses.
[2024-06-19T07:16:54.260+0000] {taskinstance.py:441} INFO - ::group::Post task execution logs
[2024-06-19T07:16:54.280+0000] {taskinstance.py:2905} ERROR - Task failed with exception
Traceback (most recent call last):
  File "/home/airflow/.local/lib/python3.12/site-packages/airflow/models/taskinstance.py", line 465, in _execute_task
    result = _execute_callable(context=context, **execute_callable_kwargs)
             ^^^^^^^^^^^^^^^^^^^^^^^^^^^^^^^^^^^^^^^^^^^^^^^^^^^^^^^^^^^^^
  File "/home/airflow/.local/lib/python3.12/site-packages/airflow/models/taskinstance.py", line 432, in _execute_callable
    return execute_callable(context=context, **execute_callable_kwargs)
           ^^^^^^^^^^^^^^^^^^^^^^^^^^^^^^^^^^^^^^^^^^^^^^^^^^^^^^^^^^^^
  File "/home/airflow/.local/lib/python3.12/site-packages/airflow/models/baseoperator.py", line 401, in wrapper
    return func(self, *args, **kwargs)
           ^^^^^^^^^^^^^^^^^^^^^^^^^^^
  File "/home/airflow/.local/lib/python3.12/site-packages/airflow/operators/python.py", line 235, in execute
    return_value = self.execute_callable()
                   ^^^^^^^^^^^^^^^^^^^^^^^
  File "/home/airflow/.local/lib/python3.12/site-packages/airflow/operators/python.py", line 252, in execute_callable
    return self.python_callable(*self.op_args, **self.op_kwargs)
           ^^^^^^^^^^^^^^^^^^^^^^^^^^^^^^^^^^^^^^^^^^^^^^^^^^^^^
  File "/opt/airflow/dags/summary_transaction.py", line 26, in extract_data
    ti.xcom_push(key='transaction_data', value=df.to_json())
  File "/home/airflow/.local/lib/python3.12/site-packages/airflow/utils/session.py", line 79, in wrapper
    return func(*args, session=session, **kwargs)
           ^^^^^^^^^^^^^^^^^^^^^^^^^^^^^^^^^^^^^^
  File "/home/airflow/.local/lib/python3.12/site-packages/airflow/models/taskinstance.py", line 3197, in xcom_push
    XCom.set(
  File "/home/airflow/.local/lib/python3.12/site-packages/airflow/utils/session.py", line 76, in wrapper
    return func(*args, **kwargs)
           ^^^^^^^^^^^^^^^^^^^^^
  File "/home/airflow/.local/lib/python3.12/site-packages/airflow/models/xcom.py", line 275, in set
    session.flush()
  File "/home/airflow/.local/lib/python3.12/site-packages/sqlalchemy/orm/session.py", line 3449, in flush
    self._flush(objects)
  File "/home/airflow/.local/lib/python3.12/site-packages/sqlalchemy/orm/session.py", line 3588, in _flush
    with util.safe_reraise():
  File "/home/airflow/.local/lib/python3.12/site-packages/sqlalchemy/util/langhelpers.py", line 70, in __exit__
    compat.raise_(
  File "/home/airflow/.local/lib/python3.12/site-packages/sqlalchemy/util/compat.py", line 211, in raise_
    raise exception
  File "/home/airflow/.local/lib/python3.12/site-packages/sqlalchemy/orm/session.py", line 3549, in _flush
    flush_context.execute()
  File "/home/airflow/.local/lib/python3.12/site-packages/sqlalchemy/orm/unitofwork.py", line 456, in execute
    rec.execute(self)
  File "/home/airflow/.local/lib/python3.12/site-packages/sqlalchemy/orm/unitofwork.py", line 630, in execute
    util.preloaded.orm_persistence.save_obj(
  File "/home/airflow/.local/lib/python3.12/site-packages/sqlalchemy/orm/persistence.py", line 245, in save_obj
    _emit_insert_statements(
  File "/home/airflow/.local/lib/python3.12/site-packages/sqlalchemy/orm/persistence.py", line 1097, in _emit_insert_statements
    c = connection._execute_20(
        ^^^^^^^^^^^^^^^^^^^^^^^
  File "/home/airflow/.local/lib/python3.12/site-packages/sqlalchemy/engine/base.py", line 1710, in _execute_20
    return meth(self, args_10style, kwargs_10style, execution_options)
           ^^^^^^^^^^^^^^^^^^^^^^^^^^^^^^^^^^^^^^^^^^^^^^^^^^^^^^^^^^^
  File "/home/airflow/.local/lib/python3.12/site-packages/sqlalchemy/sql/elements.py", line 334, in _execute_on_connection
    return connection._execute_clauseelement(
           ^^^^^^^^^^^^^^^^^^^^^^^^^^^^^^^^^^
  File "/home/airflow/.local/lib/python3.12/site-packages/sqlalchemy/engine/base.py", line 1577, in _execute_clauseelement
    ret = self._execute_context(
          ^^^^^^^^^^^^^^^^^^^^^^
  File "/home/airflow/.local/lib/python3.12/site-packages/sqlalchemy/engine/base.py", line 1953, in _execute_context
    self._handle_dbapi_exception(
  File "/home/airflow/.local/lib/python3.12/site-packages/sqlalchemy/engine/base.py", line 2138, in _handle_dbapi_exception
    util.raise_(exc_info[1], with_traceback=exc_info[2])
  File "/home/airflow/.local/lib/python3.12/site-packages/sqlalchemy/util/compat.py", line 211, in raise_
    raise exception
  File "/home/airflow/.local/lib/python3.12/site-packages/sqlalchemy/engine/base.py", line 1910, in _execute_context
    self.dialect.do_execute(
  File "/home/airflow/.local/lib/python3.12/site-packages/sqlalchemy/engine/default.py", line 736, in do_execute
    cursor.execute(statement, parameters)
  File "/usr/local/lib/python3.12/encodings/utf_8.py", line 15, in decode
    def decode(input, errors='strict'):
    
  File "/home/airflow/.local/lib/python3.12/site-packages/airflow/models/taskinstance.py", line 2613, in signal_handler
    raise AirflowTaskTerminated("Task received SIGTERM signal")
airflow.exceptions.AirflowTaskTerminated: Task received SIGTERM signal
[2024-06-19T07:16:54.315+0000] {taskinstance.py:1206} INFO - Marking task as UP_FOR_RETRY. dag_id=summary_transaction, task_id=extract_task, run_id=scheduled__2024-06-18T07:11:00+00:00, execution_date=20240618T071100, start_date=20240619T071633, end_date=20240619T071654
[2024-06-19T07:16:54.512+0000] {process_utils.py:80} INFO - Process psutil.Process(pid=10747, status='terminated', exitcode=2, started='07:16:33') (10747) terminated with exit code 2
